Workbook

Sheet Resumen Financiero
A1: Obra | B1: Monto Contrato | C1: EJECUTADO | D1: DESEMBOLSADO | E1: FLUJO DE CAJA | F1: Por cobrar | G1: Utilidad Bruta | H1: Flujo de Caja2 | I1: % Avance Facturado | J1: % Avance Cobrado | K1: Saldo por Ejecutar | L1: Estado
A2: FATIMA | B2: =[1]!Panel_Control[[#This Row],[Monto del Contrato]] -> 38605.82 | C2: =[1]!Panel_Control[[#This Row],[Total Ejecutado]] -> 29154.8 | D2: =[1]!Panel_Control[[#This Row],[Total Ingresos]] -> 38605.82 | E2: =D2-C2 -> 9451.02 | F2: =B2-D2 -> 0 | G2: =C2-E2 -> 19703.78 | H2: =E2 -> 9451.02 | I2: =C2/B2 -> 0.75519183 | J2: =D2/B2 -> 1 | K2: =B2-C2 -> 9451.02 | L2: CULMINADA
A3: CACUTE SUELOS CAFÉ | B3: =[1]!Panel_Control[[#This Row],[Monto del Contrato]] -> 580 | C3: =[1]!Panel_Control[[#This Row],[Total Ejecutado]] -> 315 | D3: =[1]!Panel_Control[[#This Row],[Total Ingresos]] -> 406 | E3: =D3-C3 -> 91 | F3: =B3-D3 -> 174 | G3: =C3-E3 -> 224 | H3: =E3 -> 91 | I3: =C3/B3 -> 0.54310345 | J3: =D3/B3 -> 0.7 | K3: =B3-C3 -> 265 | L3: ACTIVA
A4: CACUTE SUELOS GALPON | B4: =[1]!Panel_Control[[#This Row],[Monto del Contrato]] -> 580 | C4: =[1]!Panel_Control[[#This Row],[Total Ejecutado]] -> 315 | D4: =[1]!Panel_Control[[#This Row],[Total Ingresos]] -> 406 | E4: =D4-C4 -> 91 | F4: =B4-D4 -> 174 | G4: =C4-E4 -> 224 | H4: =E4 -> 91 | I4: =C4/B4 -> 0.54310345 | J4: =D4/B4 -> 0.7 | K4: =B4-C4 -> 265 | L4: ACTIVA
A5: ESTANCIA 2ET | B5: =[1]!Panel_Control[[#This Row],[Monto del Contrato]] -> 10524 | C5: =[1]!Panel_Control[[#This Row],[Total Ejecutado]] -> 3236.57 | D5: =[1]!Panel_Control[[#This Row],[Total Ingresos]] -> 6314 | E5: =D5-C5 -> 3077.43 | F5: =B5-D5 -> 4210 | G5: =C5-E5 -> 159.14 | H5: =E5 -> 3077.43 | I5: =C5/B5 -> 0.30754181 | J5: =D5/B5 -> 0.59996199 | K5: =B5-C5 -> 7287.43 | L5: ACTIVA
A6: ESTANCIA ELECTRODOMESTICOS | B6: =[1]!Panel_Control[[#This Row],[Monto del Contrato]] -> 5525 | C6: =[1]!Panel_Control[[#This Row],[Total Ejecutado]] -> 276.25 | D6: =[1]!Panel_Control[[#This Row],[Total Ingresos]] -> 5525 | E6: =D6-C6 -> 5248.75 | F6: =B6-D6 -> 0 | G6: =C6-E6 -> -4972.5 | H6: =E6 -> 5248.75 | I6: =C6/B6 -> 0.05 | J6: =D6/B6 -> 1 | K6: =B6-C6 -> 5248.75 | L6: ACTIVA
A7: ESTANCIA LENCERIA | B7: =[1]!Panel_Control[[#This Row],[Monto del Contrato]] -> 1743.75 | C7: =[1]!Panel_Control[[#This Row],[Total Ejecutado]] -> 87.18 | D7: =[1]!Panel_Control[[#This Row],[Total Ingresos]] -> 1743.75 | E7: =D7-C7 -> 1656.57 | F7: =B7-D7 -> 0 | G7: =C7-E7 -> -1569.39 | H7: =E7 -> 1656.57 | I7: =C7/B7 -> 0.049995699 | J7: =D7/B7 -> 1 | K7: =B7-C7 -> 1656.57 | L7: ACTIVA
A8: SAN JUAN | B8: =[1]!Panel_Control[[#This Row],[Monto del Contrato]] -> 8484.79 | C8: =[1]!Panel_Control[[#This Row],[Total Ejecutado]] -> 4512.29 | D8: =[1]!Panel_Control[[#This Row],[Total Ingresos]] -> 5094 | E8: =D8-C8 -> 581.71 | F8: =B8-D8 -> 3390.79 | G8: =C8-E8 -> 3930.58 | H8: =E8 -> 581.71 | I8: =C8/B8 -> 0.53180927 | J8: =D8/B8 -> 0.60036842 | K8: =B8-C8 -> 3972.5 | L8: ACTIVA
A9: CONSOLIDADO OBRAS | B9: =SUM(B2:B8) -> 66043.36 | C9: =SUM(C2:C8) -> 37897.09 | D9: =SUM(D2:D8) -> 58094.57 | E9: =D9-C9 -> 20197.48 | F9: =B9-D9 -> 7948.79 | G9: =C9-E9 -> 17699.61 | H9: =E9 -> 20197.48 | I9: =C9/B9 -> 0.57382135 | J9: =D9/B9 -> 0.87964286 | K9: =B9-C9 -> 28146.27 | L9: ACTIVA

Sheet Dashboard
A1: DASHBOARD DE CONTROL DE OBRA (COLEGIO NUESTRA SEÑORA DEL FATIMA)
A4: PRESUPUESTO TOTAL | C4: GASTO EJECUTADO | E4: SALDO DISPONIBLE | G4: % EJECUCIÓN FINANCIERA
A5: =Presupuesto!E11 -> 43821.59 | C5: =Compras_Materiales!L120+Pago_Obreros!M47 -> 21784.026 | E5: =A5-C5 -> 22037.564 | G5: =C5/A5 -> 0.49710717
A7: ABONADO | C7: GASTO EJECUTADO | E7: SALDO DISPONIBLE | G7: % EJECUCIÓN FINANCIERA
A8: =B23 -> 33203.99 | C8: =C14 -> 21784.026 | E8: =A8-C8 -> 11419.964 | G8: =C8/A8 -> 0.65606653
A11: Categoría de Gasto | B11: Presupuestado ($) | C11: Ejecutado Real ($) | D11: Saldo / Variación ($) | E11: % Ejecución
A12: Materiales e Insumos | B12: =Presupuesto!E7 -> 33821.59 | C12: =Compras_Materiales!L120 -> 17239.126 | D12: =B12-C12 -> 16582.464 | E12: =C12/B12 -> 0.50970775
A13: Mano de Obra (Obreros) | B13: =Presupuesto!E10 -> 10000 | C13: =Pago_Obreros!M47 -> 4544.9 | D13: =B13-C13 -> 5455.1 | E13: =C13/B13 -> 0.45449
A14: TOTAL OBRA | B14: =SUM(B12:B13) -> 43821.59 | C14: =SUM(C12:C13) -> 21784.026 | D14: =SUM(D12:D13) -> 22037.564 | E14: =C14/B14 -> 0.49710717
A16: Categoría de Gasto | B16: Presupuestado ($) | C16: Ejecutado Real ($) | D16: Saldo / Variación ($) | E16: % Ejecución
A17: Materiales e Insumos | B17: 23203.73 | C17: =C12 -> 17239.126 | D17: =B17-C17 -> 5964.6036 | E17: =C17/B17 -> 0.74294634
A18: Mano de Obra (Obreros) | B18: 10000 | C18: =C13 -> 4544.9 | D18: =B18-C18 -> 5455.1 | E18: =C18/B18 -> 0.45449
A19: TOTAL OBRA | B19: =SUM(B17:B18) -> 33203.73 | C19: =SUM(C17:C18) -> 21784.026 | D19: =SUM(D17:D18) -> 11419.704 | E19: =C19/B19 -> 0.65607166
A21: Desembolsado | B21: 22586.39 | C21: 1 | D21: 22586.39 | E21: Baños
A22: Desembolsado | B22: 10617.6 | C22: 0.5 | D22: 21235.2 | E22: Aulas
A23: Total Desembolsado | B23: =B21+B22 -> 33203.99 | D23: =D21+D22 -> 43821.59
A24: Por desembolsar | B24: =B23-B14 -> -10617.6

Sheet Presupuesto
A1: PRESUPUESTO BASE DE LA OBRA
A4: Item | B4: Descripción de Partida | C4: Unidad | D4: Cantidad | E4: Costo Total Presupuestado ($)
A5: 1.0 | B5: MATERIALES E INSUMOS
A6: 1.1 | B6: MATERIALES, INSUMOS, SERVICIOS | E6: 33821.59
A7: SUB | B7: Subtotal Categoría Materiales e insumos | E7: =SUM(E6:E6) -> 33821.59
A8: 2.0 | B8: MANO DE OBRA
A9: 2.1 | B9: Nomina Obreros | C9: Dia | D9: 6 | E9: 10000
A10: SUB | B10: Subtotal Nomina Obreros | E10: =E9 -> 10000
B11: TOTAL PRESUPUESTO DE OBRA | E11: =E7+E10 -> 43821.59

Sheet Compras_Materiales
A1: REGISTRO DE COMPRAS DE MATERIALES E INSUMOS
A4: ID Compra | B4: Fecha | C4: Proveedor | D4: N° Factura | E4: Descripción del Material | F4: Proyecto | G4: Cantidad | H4: Precio Unitario Bs | I4: Precio Total Bs | J4: Tasa | K4: Precio Unitario ($) | L4: Precio Total ($) | M4: Estado / Observación
E5: Aire acondicionado | F5: OFICINA | G5: 1 | I5: =Tabla4[[#This Row],[Cantidad]]*Tabla4[[#This Row],[Precio Unitario Bs]] -> 0 | K5: 270 | L5: =G5*K5 -> 270
E6: Audicon Consultores | F6: AULAS | G6: 1 | I6: =Tabla4[[#This Row],[Cantidad]]*Tabla4[[#This Row],[Precio Unitario Bs]] -> 0 | K6: 726 | L6: =G6*K6 -> 726
A7: MAT-001 | B7: 46233 | C7: TIENDAS MONSALVE | D7: 7992 | E7: PINTURA CAUCHO DEKORAL BLANCO 4GL | F7: AULAS | G7: 2 | I7: =Tabla4[[#This Row],[Cantidad]]*Tabla4[[#This Row],[Precio Unitario Bs]] -> 0 | K7: 125.7 | L7: =G7*K7 -> 251.4 | M7: Entregado en obra
A8: MAT-002 | B8: 46233 | C8: TIENDAS MONSALVE | D8: 7992 | E8: SELLACRIL MONTANA SELLADOR ANTI 4GL | F8: AULAS | G8: 1 | I8: =Tabla4[[#This Row],[Cantidad]]*Tabla4[[#This Row],[Precio Unitario Bs]] -> 0 | K8: 72.15 | L8: =G8*K8 -> 72.15 | M8: Entregado en obra
A9: MAT-003 | B9: 46233 | C9: TIENDAS MONSALVE | D9: 7992 | E9: BOBINA KRAFT 60CM X 180 METROS | F9: AULAS | G9: 1 | I9: =Tabla4[[#This Row],[Cantidad]]*Tabla4[[#This Row],[Precio Unitario Bs]] -> 0 | K9: 29.44 | L9: =G9*K9 -> 29.44 | M9: Entregado en obra
A10: MAT-004 | B10: 46233 | C10: TIENDAS MONSALVE | D10: 7992 | E10: IVA | F10: AULAS | G10: 1 | I10: =Tabla4[[#This Row],[Cantidad]]*Tabla4[[#This Row],[Precio Unitario Bs]] -> 0 | K10: 36.37 | L10: =G10*K10 -> 36.37 | M10: Entregado en obra
A11: MAT-005 | B11: 46233 | C11: TIENDAS MONSALVE | D11: 11476 | E11: SELLAGRIL MONTANA SELLADOR ANTIALCALIN | F11: AULAS | G11: 1 | I11: =Tabla4[[#This Row],[Cantidad]]*Tabla4[[#This Row],[Precio Unitario Bs]] -> 0 | K11: 72.15 | L11: =G11*K11 -> 72.15 | M11: Entregado en obra
A12: MAT-006 | B12: 46233 | C12: TIENDAS MONSALVE | D12: 11476 | E12: IVA | F12: AULAS | G12: 1 | I12: =Tabla4[[#This Row],[Cantidad]]*Tabla4[[#This Row],[Precio Unitario Bs]] -> 0 | K12: 11.54 | L12: =G12*K12 -> 11.54 | M12: Entregado en obra
A13: MAT-007 | B13: 46204 | C13: MATERIALES LOS ANDES | D13: 1771545 | E13: CEMENTO BLANCO 20KG SACO ARGOS | F13: AULAS | G13: 1 | I13: =Tabla4[[#This Row],[Cantidad]]*Tabla4[[#This Row],[Precio Unitario Bs]] -> 0 | K13: 15.458313 | L13: =G13*K13 -> 15.458313
A14: MAT-008 | B14: 46204 | C14: MATERIALES LOS ANDES | D14: 1771545 | E14: MAXICAL DE 10KG | F14: AULAS | G14: 10 | I14: =Tabla4[[#This Row],[Cantidad]]*Tabla4[[#This Row],[Precio Unitario Bs]] -> 0 | K14: 6.1049918 | L14: =G14*K14 -> 61.049918
A15: MAT-009 | B15: 46204 | C15: MATERIALES LOS ANDES | D15: 1771545 | E15: CEMENTO GRIS 42.5KG SACO CATATUMBO | F15: AULAS | G15: 110 | I15: =Tabla4[[#This Row],[Cantidad]]*Tabla4[[#This Row],[Precio Unitario Bs]] -> 0 | K15: 13.746474 | L15: =G15*K15 -> 1512.1122
A16: MAT-010 | B16: 46204 | C16: MATERIALES LOS ANDES | D16: 1771545 | E16: BLOQUE D/ARCILLA 15 X 20 X 30 CM | F16: AULAS | G16: 1020 | I16: =Tabla4[[#This Row],[Cantidad]]*Tabla4[[#This Row],[Precio Unitario Bs]] -> 0 | K16: 0.87398042 | L16: =G16*K16 -> 891.46003
A17: MAT-011 | B17: 46204 | C17: MATERIALES LOS ANDES | D17: 1771545 | E17: ARCO P/SEGUETA 12" THT54166 TOTAL | F17: AULAS | G17: 1 | I17: =Tabla4[[#This Row],[Cantidad]]*Tabla4[[#This Row],[Precio Unitario Bs]] -> 0 | K17: 6.4955199 | L17: =G17*K17 -> 6.4955199
A18: MAT-012 | B18: 46204 | C18: MATERIALES LOS ANDES | D18: 1771545 | E18: MARCO P/PUERTA DE 10 Cm X 0.90mm X 5.15M | F18: AULAS | G18: 8 | I18: =Tabla4[[#This Row],[Cantidad]]*Tabla4[[#This Row],[Precio Unitario Bs]] -> 0 | K18: 15.319984 | L18: =G18*K18 -> 122.55988
A19: MAT-013 | B19: 46204 | C19: MATERIALES LOS ANDES | D19: 1771545 | E19: MANDARRIA 2K C/MANGO INGCO | F19: AULAS | G19: 2 | I19: =Tabla4[[#This Row],[Cantidad]]*Tabla4[[#This Row],[Precio Unitario Bs]] -> 0 | K19: 16.362817 | L19: =G19*K19 -> 32.725634
A20: MAT-014 | B20: 46204 | C20: MATERIALES LOS ANDES | D20: 1771545 | E20: MARTILLO M/MAD.29MM TOTAL | F20: AULAS | G20: 2 | I20: =Tabla4[[#This Row],[Cantidad]]*Tabla4[[#This Row],[Precio Unitario Bs]] -> 0 | K20: 8.5268875 | L20: =G20*K20 -> 17.053775
A21: MAT-015 | B21: 46204 | C21: MATERIALES LOS ANDES | D21: 1771545 | E21: JGO D/RODIL 3PZ FUNDA C/BAND P/CORT CEBR | F21: AULAS | G21: 2 | I21: =Tabla4[[#This Row],[Cantidad]]*Tabla4[[#This Row],[Precio Unitario Bs]] -> 0 | K21: 8.6475764 | L21: =G21*K21 -> 17.295153
A22: MAT-016 | B22: 46204 | C22: MATERIALES LOS ANDES | D22: 1771545 | E22: TIRRO VERDE 401 ENMASCARAR-PINTAR NORMAL | F22: AULAS | G22: 1 | I22: =Tabla4[[#This Row],[Cantidad]]*Tabla4[[#This Row],[Precio Unitario Bs]] -> 0 | K22: 3.4755234 | L22: =G22*K22 -> 3.4755234
A23: MAT-017 | B23: 46204 | C23: MATERIALES LOS ANDES | D23: 1771545 | E23: TIRRO 1*55MTS 3M | F23: AULAS | G23: 1 | I23: =Tabla4[[#This Row],[Cantidad]]*Tabla4[[#This Row],[Precio Unitario Bs]] -> 0 | K23: 3.9423945 | L23: =G23*K23 -> 3.9423945
A24: MAT-018 | B24: 46204 | C24: MATERIALES LOS ANDES | D24: 1771545 | E24: CAJA OCTAGONAL ASTM D-1784 NEMA TC-3 | F24: AULAS | G24: 2 | I24: =Tabla4[[#This Row],[Cantidad]]*Tabla4[[#This Row],[Precio Unitario Bs]] -> 0 | K24: 1.2536062 | L24: =G24*K24 -> 2.5072124
... A31: MAT-025 | B31: 46235 | C31: MATERIALES LOS ANDES | D31: 1771546 | E31: IVA | F31: AULAS | G31: 1 | I31: =Tabla4[[#This Row],[Cantidad]]*Tabla4[[#This Row],[Precio Unitario Bs]] -> 0 | K31: 177.97 | L31: =G31*K31 -> 177.97
A32: MAT-026 | B32: 46237 | C32: MATERIALES LOS ANDES | D32: 1772631 | E32: PLASTICO NEGRO 3MTS X 450MICRAS XMTS | F32: AULAS | G32: 20 | I32: =Tabla4[[#This Row],[Cantidad]]*Tabla4[[#This Row],[Precio Unitario Bs]] -> 0 | K32: 5.85 | L32: =G32*K32 -> 117 | M32: Entregado en obra
A33: MAT-027 | B33: 46237 | C33: MATERIALES LOS ANDES | D33: 1772631 | E33: GUANTE ANTICORTE AZUL YOU GAIN | F33: AULAS | G33: 6 | I33: =Tabla4[[#This Row],[Cantidad]]*Tabla4[[#This Row],[Precio Unitario Bs]] -> 0 | K33: 1.59 | L33: =G33*K33 -> 9.54 | M33: Entregado en obra
A34: MAT-028 | B34: 46237 | C34: MATERIALES LOS ANDES | D34: 1772631 | E34: LENTE SEGURIDAD SUP CLARO INFINITY | F34: AULAS | G34: 6 | I34: =Tabla4[[#This Row],[Cantidad]]*Tabla4[[#This Row],[Precio Unitario Bs]] -> 0 | K34: 1.59 | L34: =G34*K34 -> 9.54 | M34: Entregado en obra
A35: MAT-029 | B35: 46237 | C35: MATERIALES LOS ANDES | D35: 1772631 | E35: IVA | F35: AULAS | G35: 1 | I35: =Tabla4[[#This Row],[Cantidad]]*Tabla4[[#This Row],[Precio Unitario Bs]] -> 0 | K35: 21.78 | L35: =G35*K35 -> 21.78 | M35: Entregado en obra
A36: MAT-030 | B36: 46237 | C36: ANDAMIOS CA | D36: 2 | E36: TABLEROS PARA ANDAMIOS | F36: AULAS | G36: 1 | I36: =Tabla4[[#This Row],[Cantidad]]*Tabla4[[#This Row],[Precio Unitario Bs]] -> 0 | K36: 140 | L36: =G36*K36 -> 140 | M36: Entregado en obra
A37: MAT-031 | B37: 46237 | C37: FERRELECTRICA GONZUR CA | D37: 19280 | E37: TAPA GALVANIZADA 1/2" | F37: AULAS | G37: 5 | I37: =Tabla4[[#This Row],[Cantidad]]*Tabla4[[#This Row],[Precio Unitario Bs]] -> 0 | K37: 1.4 | L37: =G37*K37 -> 7
A38: MAT-032 | B38: 46237 | C38: FERRELECTRICA GONZUR CA | D38: 19280 | E38: IVA | F38: AULAS | G38: 1 | I38: =Tabla4[[#This Row],[Cantidad]]*Tabla4[[#This Row],[Precio Unitario Bs]] -> 0 | K38: 1.12 | L38: =G38*K38 -> 1.12
A39: MAT-033 | B39: 46237 | C39: FARMACIA LIDERFARMA URDANETA CA | D39: 20416 | E39: TAPABOCA KN95 BLANCO | F39: AULAS | G39: 7 | I39: =Tabla4[[#This Row],[Cantidad]]*Tabla4[[#This Row],[Precio Unitario Bs]] -> 0 | K39: 0.27 | L39: =G39*K39 -> 1.89
A40: MAT-034 | B40: 46237 | C40: FARMACIA LIDERFARMA URDANETA CA | D40: 20416 | E40: IVA | F40: AULAS | G40: 1 | I40: =Tabla4[[#This Row],[Cantidad]]*Tabla4[[#This Row],[Precio Unitario Bs]] -> 0 | K40: 0.3 | L40: =G40*K40 -> 0.3
A41: MAT-035 | B41: 46237 | C41: MATERIALES LOS ANDES | D41: 2165997 | E41: PALA PLASTICA MEDIANA | F41: AULAS | G41: 1 | I41: =Tabla4[[#This Row],[Cantidad]]*Tabla4[[#This Row],[Precio Unitario Bs]] -> 0 | K41: 2.45 | L41: =G41*K41 -> 2.45
A42: MAT-036 | B42: 46237 | C42: MATERIALES LOS ANDES | D42: 2165997 | E42: TENAZA CABILLERA 10" | F42: AULAS | G42: 1 | I42: =Tabla4[[#This Row],[Cantidad]]*Tabla4[[#This Row],[Precio Unitario Bs]] -> 0 | K42: 9.26 | L42: =G42*K42 -> 9.26
A43: MAT-037 | B43: 46237 | C43: MATERIALES LOS ANDES | D43: 2165997 | E43: TENAZA CABILLERA 8" | F43: AULAS | G43: 1 | I43: =Tabla4[[#This Row],[Cantidad]]*Tabla4[[#This Row],[Precio Unitario Bs]] -> 0 | K43: 6.59 | L43: =G43*K43 -> 6.59
A44: MAT-038 | B44: 46237 | C44: MATERIALES LOS ANDES | D44: 2165997 | E44: ALAMBRE GALVANIZADO C-17,5 ROLLO 750gr ALMAGAL | F44: AULAS | G44: 5 | I44: =Tabla4[[#This Row],[Cantidad]]*Tabla4[[#This Row],[Precio Unitario Bs]] -> 0 | K44: 3.73 | L44: =G44*K44 -> 18.65
A45: MAT-039 | B45: 46238 | C45: MATERIALES LOS ANDES | D45: 2165997 | E45: IVA | F45: AULAS | G45: 1 | I45: =Tabla4[[#This Row],[Cantidad]]*Tabla4[[#This Row],[Precio Unitario Bs]] -> 0 | K45: 5.91 | L45: =G45*K45 -> 5.91
A46: MAT-040 | B46: 46238 | C46: FERRELECTRICA GONZUR CA | D46: 19299 | E46: SOLDADURA PVC 1/64 CONDICIONES HUMEDAS | F46: AULAS | G46: 1 | I46: =Tabla4[[#This Row],[Cantidad]]*Tabla4[[#This Row],[Precio Unitario Bs]] -> 0 | K46: 6.25 | L46: =G46*K46 -> 6.25
A47: MAT-041 | B47: 46238 | C47: FERRELECTRICA GONZUR CA | D47: 19299 | E47: LIMPIADOR REMOVEDOR 118CM PAVCO | F47: AULAS | G47: 1 | I47: =Tabla4[[#This Row],[Cantidad]]*Tabla4[[#This Row],[Precio Unitario Bs]] -> 0 | K47: 5.16 | L47: =G47*K47 -> 5.16
A48: MAT-042 | B48: 46238 | C48: FERRELECTRICA GONZUR CA | D48: 19299 | E48: TAPA SOLDADA 1/2" AGUA FRIA | F48: AULAS | G48: 4 | I48: =Tabla4[[#This Row],[Cantidad]]*Tabla4[[#This Row],[Precio Unitario Bs]] -> 0 | K48: 0.84 | L48: =G48*K48 -> 3.36
...

Sheet Pago_Obreros
A1: CONTROL SEMANAL DE NÓMINA Y PAGO A OBREROS
A4: N° Sem | B4: Inicio labor | C4: Fecha Pago | D4: Nombre del Trabajador | E4: CI | F4: N° Cuenta | G4: Banco | H4: Cargo / Rol | I4: Días Trabajados | J4: Pago Diario ($) | K4: Bonificación ($) | L4: Deducciones ($) | M4: Total Pagado ($) | N4: Notas / Frente de Trabajo
A5: 1 | B5: 46239 | C5: 46239 | D5: CARPINTERO | H5: CARPINTERO | I5: 21 | J5: 51.9 | K5: 0 | L5: 0 | M5: =IF(I5<>"", (I5*J5)+K5-L5, 0) -> 1089.9 | N5: CLOSETS Y PUERTAS
A6: 1 | B6: 46237 | C6: 46241 | D6: JEANETTE CONTRERAS | H6: INGENIERO | I6: 6 | J6: 33.3 | K6: 0.2 | L6: 0 | M6: =(I6*J6)+K6-L6 -> 200 | N6: DEMOLICION
A7: 1 | B7: 46237 | C7: 46241 | D7: PAOLA RANGEL | H7: ARQUITECTO | I7: 0 | J7: 30 | K7: 0 | L7: 0 | M7: =(I7*J7)+K7-L7 -> 0 | N7: DEMOLICION
A8: 1 | B8: 46237 | C8: 46241 | D8: JAVIER BARAZARTE | E8: 16654228 | H8: MAESTRO | I8: 4.5 | J8: 43.3 | K8: 0.15 | L8: 0 | M8: =(I8*J8)+K8-L8 -> 195 | N8: DEMOLICION
A9: 1 | B9: 46237 | C9: 46241 | D9: JESUS ENRIQUE ROJAS ROJAS | E9: 11953356 | F9: 01370032060007146771 | G9: SOFITASA | H9: OBRERO | I9: 5 | J9: 20 | K9: 0 | L9: 0 | M9: =(I9*J9)+K9-L9 -> 100 | N9: DEMOLICION
A10: 1 | B10: 46237 | C10: 46241 | D10: OBDULIO JOSE ZAMBRANO SANCHEZ | E10: 17129701 | F10: 01020744460000029010 | G10: VENEZUELA | H10: OBRERO | I10: 5 | J10: 20 | K10: 0 | L10: 0 | M10: =(I10*J10)+K10-L10 -> 100 | N10: DEMOLICION
A11: 1 | B11: 46237 | C11: 46241 | D11: WISTER DE JESUS NIETO ALBARRAN | E11: 18620608 | F11: 01080374860100057756 | G11: PROVINCIAL | H11: OBRERO | I11: 3 | J11: 20 | K11: 0 | L11: 0 | M11: =(I11*J11)+K11-L11 -> 60 | N11: DEMOLICION
A12: 1 | B12: 46237 | C12: 46241 | D12: JOSE GREGORIO ALEMAN ALBARRAN | E12: 14401299 | F12: 01080114161500001875 | G12: PROVINCIAL | H12: OBRERO | I12: 5 | J12: 20 | K12: 0 | L12: 0 | M12: =(I12*J12)+K12-L12 -> 100 | N12: DEMOLICION
A13: 1 | B13: 46237 | C13: 46241 | D13: JUAN CARLOS TORO ROJAS | E13: 26749609 | F13: 01020744440000675312 | G13: VENEZUELA | H13: OBRERO | I13: 5 | J13: 20 | K13: 0 | L13: 0 | M13: =IF(I13<>"", (I13*J13)+K13-L13, 0) -> 100 | N13: DEMOLICION
A14: 1 | B14: 46237 | C14: 46241 | D14: YONNI RODRIGUEZ | E14: 17521849 | F14: 01020744410000736659 | G14: VENEZUELA | H14: OBRERO | I14: 2 | J14: 20 | K14: 0 | L14: 0 | M14: =IF(I14<>"", (I14*J14)+K14-L14, 0) -> 40 | N14: DEMOLICION
A15: 1 | B15: 46237 | C15: 46241 | D15: GABRIEL VERA | E15: 21184006 | F15: 01020859940000544540 | G15: VENEZUELA | H15: OBRERO | I15: 2 | J15: 20 | K15: 0 | L15: 0 | M15: =IF(I15<>"", (I15*J15)+K15-L15, 0) -> 40 | N15: DEMOLICION
A16: 2 | B16: 46244 | C16: 46246 | D16: GABRIEL VERA | E16: 17662480 | F16: 04120788608 | G16: Pgo Movil | H16: OBRERO | I16: 3 | J16: 20 | K16: 0 | L16: 0 | M16: =IF(I16<>"", (I16*J16)+K16-L16, 0) -> 60 | N16: AULAS/BAÑOS
A17: 2 | B17: 46244 | C17: 46249 | D17: JEANETTE CONTRERAS | H17: INGENIERO | I17: 6 | J17: 33.3 | K17: 0.2 | L17: 0 | M17: =IF(I17<>"", (I17*J17)+K17-L17, 0) -> 200 | N17: AULAS/BAÑOS
A18: 2 | B18: 46244 | C18: 46249 | D18: PAOLA RANGEL | H18: ARQUITECTO | I18: 6 | J18: 30 | K18: 0 | L18: 0 | M18: =IF(I18<>"", (I18*J18)+K18-L18, 0) -> 180 | N18: AULAS/BAÑOS
A19: 2 | B19: 46244 | C19: 46249 | D19: JAVIER BARAZARTE | E19: 16654228 | H19: MAESTRO | I19: 6 | J19: 43.3 | K19: 0.2 | L19: 0 | M19: =IF(I19<>"", (I19*J19)+K19-L19, 0) -> 260 | N19: AULAS/BAÑOS
A20: 2 | B20: 46244 | C20: 46249 | D20: JESUS ROJAS LOBO | E20: 14806836 | F20: 01020744440000265450 | G20: VENEZUELA | H20: ALBAÑIL | I20: 6 | J20: 30 | K20: 0 | L20: 0 | M20: =IF(I20<>"", (I20*J20)+K20-L20, 0) -> 180 | N20: AULAS/BAÑOS
A21: 2 | B21: 46244 | C21: 46249 | D21: WISTER DE JESUS NIETO ALBARRAN | E21: 18620608 | F21: 01080374860100057756 | G21: PROVINCIAL | H21: ALBAÑIL | I21: 6 | J21: 30 | K21: 0 | L21: 0 | M21: =IF(I21<>"", (I21*J21)+K21-L21, 0) -> 180 | N21: AULAS/BAÑOS
A22: 2 | B22: 46244 | C22: 46249 | D22: JESUS ENRIQUE ROJAS ROJAS | E22: 11953356 | F22: 01370032060007146771 | G22: SOFITASA | H22: ALBAÑIL | I22: 6 | J22: 30 | K22: 0 | L22: 0 | M22: =IF(I22<>"", (I22*J22)+K22-L22, 0) -> 180 | N22: AULAS/BAÑOS
A23: 2 | B23: 46244 | C23: 46249 | D23: EDIKSON PEÑA PEREZ | E23: 14699138 | F23: 01080345490100171135 | G23: PROVINCIAL | H23: ALBAÑIL | I23: 6 | J23: 30 | K23: 0 | L23: 0 | M23: =IF(I23<>"", (I23*J23)+K23-L23, 0) -> 180 | N23: AULAS/BAÑOS
A24: 2 | B24: 46244 | C24: 46249 | D24: GUSTAVO QUINTERO | E24: 15032245 | F24: 01560019550201306672 | H24: OBRERO | I24: 6 | J24: 20 | K24: 0 | L24: 0 | M24: =IF(I24<>"", (I24*J24)+K24-L24, 0) -> 120 | N24: AULAS/BAÑOS
A25: 2 | B25: 46244 | C25: 46249 | D25: JOSE GREGORIO ALEMAN ALBARRAN | E25: 14401299 | F25: 01080114161500001875 | G25: PROVINCIAL | H25: OBRERO | I25: 6 | J25: 20 | K25: 0 | L25: 0 | M25: =IF(I25<>"", (I25*J25)+K25-L25, 0) -> 120 | N25: AULAS/BAÑOS
A26: 2 | B26: 46244 | C26: 46249 | D26: OBDULIO JOSE ZAMBRANO SANCHEZ | E26: 17129701 | F26: 01020744460000029010 | G26: VENEZUELA | H26: OBRERO | I26: 6 | J26: 20 | K26: 0 | L26: 0 | M26: =IF(I26<>"", (I26*J26)+K26-L26, 0) -> 120 | N26: AULAS/BAÑOS
A27: 2 | B27: 46244 | C27: 46249 | D27: JUAN CARLOS TORO ROJAS | E27: 26749609 | F27: 01020744440000675312 | G27: VENEZUELA | H27: OBRERO | I27: 6 | J27: 20 | K27: 0 | L27: 0 | M27: =IF(I27<>"", (I27*J27)+K27-L27, 0) -> 120 | N27: AULAS/BAÑOS
A28: 2 | B28: 46244 | C28: 46249 | D28: YONNI RODRIGUEZ | E28: 17521849 | F28: 01020744410000736659 | G28: VENEZUELA | H28: OBRERO | I28: 6 | J28: 20 | K28: 0 | L28: 0 | M28: =IF(I28<>"", (I28*J28)+K28-L28, 0) -> 120 | N28: AULAS/BAÑOS
A29: 2 | B29: 46235 | C29: 46249 | D29: JOSÉ ALEXANDER GARCÍA PEREZ | E29: 11157971 | F29: 01020263960000099639 | G29: VENEZUELA | H29: ADMIN | I29: 15 | J29: 33.3 | K29: 0.5 | L29: 0 | M29: =IF(I29<>"", (I29*J29)+K29-L29, 0) -> 500 | N29: ADMIN
M37: =IF(I37<>"", (I37*J37)+K37-L37, 0) -> 0
M38: =IF(I38<>"", (I38*J38)+K38-L38, 0) -> 0
M39: =IF(I39<>"", (I39*J39)+K39-L39, 0) -> 0
M40: =IF(I40<>"", (I40*J40)+K40-L40, 0) -> 0
M41: =IF(I41<>"", (I41*J41)+K41-L41, 0) -> 0
M42: =IF(I42<>"", (I42*J42)+K42-L42, 0) -> 0
M43: =IF(I43<>"", (I43*J43)+K43-L43, 0) -> 0
M44: =IF(I44<>"", (I44*J44)+K44-L44, 0) -> 0
M45: =IF(I45<>"", (I45*J45)+K45-L45, 0) -> 0
M46: =IF(I46<>"", (I46*J46)+K46-L46, 0) -> 0
A47: TOTAL NÓMINA MANO DE OBRA | M47: =SUM(M5:M46) -> 4544.9

Sheet Pago nomina
A2: JEANETTE CONTRERAS | E2: INGENIERO | F2: 6 | G2: 33.3 | H2: 0.2 | I2: 0 | J2: =IF(F2<>"", (F2*G2)+H2-I2, 0) -> 200 | K2: 771.07 | L2: =J2*K2 -> 154214
A3: PAOLA RANGEL | E3: ARQUITECTO | F3: 6 | G3: 30 | H3: 0 | I3: 0 | J3: =IF(F3<>"", (F3*G3)+H3-I3, 0) -> 180 | K3: 771.07 | L3: =J3*K3 -> 138792.6
A4: JAVIER BARAZARTE | B4: 16654228 | E4: MAESTRO | F4: 6 | G4: 43.3 | H4: 0.2 | I4: 0 | J4: =IF(F4<>"", (F4*G4)+H4-I4, 0) -> 260 | K4: 771.07 | L4: =J4*K4 -> 200478.2
A5: JESUS ROJAS LOBO | B5: 14806836 | C5: 01020744440000265450 | D5: VENEZUELA | E5: ALBAÑIL | F5: 6 | G5: 30 | H5: 0 | I5: 0 | J5: =IF(F5<>"", (F5*G5)+H5-I5, 0) -> 180 | K5: 771.07 | L5: =J5*K5 -> 138792.6
A6: WISTER DE JESUS NIETO ALBARRAN | B6: 18620608 | C6: 01080374860100057756 | D6: PROVINCIAL | E6: ALBAÑIL | F6: 6 | G6: 30 | H6: 0 | I6: 0 | J6: =IF(F6<>"", (F6*G6)+H6-I6, 0) -> 180 | K6: 771.07 | L6: =J6*K6 -> 138792.6
A7: JESUS ENRIQUE ROJAS ROJAS | B7: 11953356 | C7: 01370032060007146771 | D7: SOFITASA | E7: ALBAÑIL | F7: 6 | G7: 30 | H7: 0 | I7: 0 | J7: =IF(F7<>"", (F7*G7)+H7-I7, 0) -> 180 | K7: 771.07 | L7: =J7*K7 -> 138792.6
A8: EDIKSON PEÑA PEREZ | B8: 14699138 | C8: 01080345490100171135 | D8: PROVINCIAL | E8: ALBAÑIL | F8: 6 | G8: 30 | H8: 0 | I8: 0 | J8: =IF(F8<>"", (F8*G8)+H8-I8, 0) -> 180 | K8: 771.07 | L8: =J8*K8 -> 138792.6
A9: GUSTAVO QUINTERO | B9: 15032245 | C9: 01560019550201306672 | E9: OBRERO | F9: 6 | G9: 20 | H9: 0 | I9: 0 | J9: =IF(F9<>"", (F9*G9)+H9-I9, 0) -> 120 | K9: 771.07 | L9: =J9*K9 -> 92528.4
A10: JOSE GREGORIO ALEMAN ALBARRAN | B10: 14401299 | C10: 01080114161500001875 | D10: PROVINCIAL | E10: OBRERO | F10: 6 | G10: 20 | H10: 0 | I10: 0 | J10: =IF(F10<>"", (F10*G10)+H10-I10, 0) -> 120 | K10: 771.07 | L10: =J10*K10 -> 92528.4
A11: OBDULIO JOSE ZAMBRANO SANCHEZ | B11: 17129701 | C11: 01020744460000029010 | D11: VENEZUELA | E11: OBRERO | F11: 6 | G11: 20 | H11: 0 | I11: 0 | J11: =IF(F11<>"", (F11*G11)+H11-I11, 0) -> 120 | K11: 771.07 | L11: =J11*K11 -> 92528.4
A12: JUAN CARLOS TORO ROJAS | B12: 26749609 | C12: 01020744440000675312 | D12: VENEZUELA | E12: OBRERO | F12: 6 | G12: 20 | H12: 0 | I12: 0 | J12: =IF(F12<>"", (F12*G12)+H12-I12, 0) -> 120 | K12: 771.07 | L12: =J12*K12 -> 92528.4
A13: YONNI RODRIGUEZ | B13: 17521849 | C13: 01020744410000736659 | D13: VENEZUELA | E13: OBRERO | F13: 6 | G13: 20 | H13: 0 | I13: 0 | J13: =IF(F13<>"", (F13*G13)+H13-I13, 0) -> 120 | K13: 771.07 | L13: =J13*K13 -> 92528.4
J15: 1960 | L15: 1511297.2

Sheet Hoja1
A1: JEANETTE CONTRERAS | E1: INGENIERO | F1: 6 | G1: 33.3 | H1: 0.2 | I1: 0 | J1: =IF(F1<>"", (F1*G1)+H1-I1, 0) -> 200
A2: PAOLA RANGEL | E2: ARQUITECTO | F2: 6 | G2: 30 | H2: 0 | I2: 0 | J2: =IF(F2<>"", (F2*G2)+H2-I2, 0) -> 180
A3: JAVIER BARAZARTE | B3: 16654228 | E3: MAESTRO | F3: 6 | G3: 43.3 | H3: 0.2 | I3: 0 | J3: =IF(F3<>"", (F3*G3)+H3-I3, 0) -> 260
A4: JESUS ROJAS LOBO | B4: 14806836 | C4: 01020744440000265450 | D4: VENEZUELA | E4: ALBAÑIL | F4: 6 | G4: 30 | H4: 0 | I4: 0 | J4: =IF(F4<>"", (F4*G4)+H4-I4, 0) -> 180
A5: WISTER DE JESUS NIETO ALBARRAN | B5: 18620608 | C5: 01080374860100057756 | D5: PROVINCIAL | E5: ALBAÑIL | F5: 6 | G5: 30 | H5: 0 | I5: 0 | J5: =IF(F5<>"", (F5*G5)+H5-I5, 0) -> 180
A6: JESUS ENRIQUE ROJAS ROJAS | B6: 11953356 | C6: 01370032060007146771 | D6: SOFITASA | E6: ALBAÑIL | F6: 6 | G6: 30 | H6: 0 | I6: 0 | J6: =IF(F6<>"", (F6*G6)+H6-I6, 0) -> 180
A7: EDIKSON PEÑA | E7: ALBAÑIL | F7: 6 | G7: 30 | H7: 0 | I7: 0 | J7: =IF(F7<>"", (F7*G7)+H7-I7, 0) -> 180
A8: GUSTAVO QUINTERO | B8: 15032245 | C8: 01560019550201306672 | E8: OBRERO | F8: 6 | G8: 20 | H8: 0 | I8: 0 | J8: =IF(F8<>"", (F8*G8)+H8-I8, 0) -> 120
A9: JOSE GREGORIO ALEMAN ALBARRAN | B9: 14401299 | C9: 01080114161500001875 | D9: PROVINCIAL | E9: OBRERO | F9: 6 | G9: 20 | H9: 0 | I9: 0 | J9: =IF(F9<>"", (F9*G9)+H9-I9, 0) -> 120
A10: OBDULIO JOSE ZAMBRANO SANCHEZ | B10: 17129701 | C10: 01020744460000029010 | D10: VENEZUELA | E10: OBRERO | F10: 6 | G10: 20 | H10: 0 | I10: 0 | J10: =IF(F10<>"", (F10*G10)+H10-I10, 0) -> 120
A11: JUAN CARLOS TORO ROJAS | B11: 26749609 | C11: 01020744440000675312 | D11: VENEZUELA | E11: OBRERO | F11: 6 | G11: 20 | H11: 0 | I11: 0 | J11: =IF(F11<>"", (F11*G11)+H11-I11, 0) -> 120
A12: YONNI RODRIGUEZ | B12: 17521849 | C12: 01020744410000736659 | D12: VENEZUELA | E12: OBRERO | F12: 6 | G12: 20 | H12: 0 | I12: 0 | J12: =IF(F12<>"", (F12*G12)+H12-I12, 0) -> 120

Sheet Nomina
H1: DIARIO
A2: ARQUITECTO | B2: PAOLA RANGEL | C2: 180 | D2: SEMANA | E2: 6 | F2: =C2*E2 -> 1080 | H2: 30
A3: INGENIERO | B3: JEANETTE CONTRERAS | C3: 200 | D3: SEMANA | E3: 6 | F3: =C3*E3 -> 1200 | H3: 33.3
A4: OBRERO | C4: 120 | D4: SEMANA | E4: 6 | F4: =C4*E4 -> 720 | G4: =F4*4 -> 2880 | H4: 20 | I4: 12.2
A5: ALBAÑIL | C5: 180 | D5: SEMANA | E5: 6 | F5: =C5*E5 -> 1080 | G5: =F5*3 -> 3240 | H5: 30 | I5: 18.7
A6: MAESTRO | C6: 260 | D6: SEMANA | E6: 6 | F6: =C6*E6 -> 1560 | G6: =F6*1 -> 1560 | H6: 43.3 | I6: 23.9
G7: =F2+F3+G5+G4+G6 -> 9960

Sheet Calculos
C1: L | D1: M | E1: M | F1: J | G1: V | H1: S
A2: JESUS ENRIQUE ROJAS ROJAS | B2: 11953356 | C2: 1 | D2: 1 | I2: 11541.64 | J2: 746.63 | K2: =I2/J2 -> 15.458313
A3: OBDULIO JOSE ZAMBRANO SANCHEZ | B3: 17129701 | C3: 1 | D3: 1 | I3: 4558.17 | J3: 746.63 | K3: =I3/J3 -> 6.1049918
A4: WISTER DE JESUS NIETO ALBARRAN | B4: 18620608 | C4: 1 | D4: 1 | I4: 10263.53 | J4: 746.63 | K4: =I4/J4 -> 13.746474
A5: JOSE GREGORIO ALEMAN ALBARRAN | B5: 14401299 | C5: 1 | D5: 1 | I5: 652.54 | J5: 746.63 | K5: =I5/J5 -> 0.87398042
A6: JUAN CARLOS TORO ROJAS | B6: 26749609 | C6: MEDIODIA | D6: 1 | I6: 4849.75 | J6: 746.63 | K6: =I6/J6 -> 6.4955199
I7: 11438.36 | J7: 746.63 | K7: =I7/J7 -> 15.319984
I8: 12216.97 | J8: 746.63 | K8: =I8/J8 -> 16.362817
I9: 6366.43 | J9: 746.63 | K9: =I9/J9 -> 8.5268875
I10: 6456.54 | J10: 746.63 | K10: =I10/J10 -> 8.6475764
I11: 2594.93 | J11: 746.63 | K11: =I11/J11 -> 3.4755234
I12: 2943.51 | J12: 746.63 | K12: =I12/J12 -> 3.9423945
I13: 935.98 | J13: 746.63 | K13: =I13/J13 -> 1.2536062
I14: 697.15 | J14: 746.63 | K14: =I14/J14 -> 0.93372889
I15: 5587.69 | J15: 746.63 | K15: =I15/J15 -> 7.4838809
I16: 1996.61 | J16: 746.63 | K16: =I16/J16 -> 2.6741626
